2024-08-27 23:27:33,882 -  nornir.core -     INFO -        run() - Running task 'get_device_info' with args {} on 4 hosts
2024-08-27 23:27:33,945 - nornir.core.task -    ERROR -      start() - Host 'vEOS2': task 'napalm_get' failed with traceback:
Traceback (most recent call last):
  File "/home/imran/Documents/Automation/Nornir/.MyNAPALMvenv/lib/python3.12/site-packages/pyeapi/eapilib.py", line 435, in send
    self.transport.endheaders(message_body=data)
  File "/usr/lib/python3.12/http/client.py", line 1331, in endheaders
    self._send_output(message_body, encode_chunked=encode_chunked)
  File "/usr/lib/python3.12/http/client.py", line 1091, in _send_output
    self.send(msg)
  File "/usr/lib/python3.12/http/client.py", line 1035, in send
    self.connect()
  File "/usr/lib/python3.12/http/client.py", line 1470, in connect
    super().connect()
  File "/usr/lib/python3.12/http/client.py", line 1001, in connect
    self.sock = self._create_connection(
                ^^^^^^^^^^^^^^^^^^^^^^^^
  File "/usr/lib/python3.12/socket.py", line 852, in create_connection
    raise exceptions[0]
  File "/usr/lib/python3.12/socket.py", line 837, in create_connection
    sock.connect(sa)
ConnectionRefusedError: [Errno 111] Connection refused

During handling of the above exception, another exception occurred:

Traceback (most recent call last):
  File "/home/imran/Documents/Automation/Nornir/.MyNAPALMvenv/lib/python3.12/site-packages/nornir/core/task.py", line 99, in start
    r = self.task(self, **self.params)
        ^^^^^^^^^^^^^^^^^^^^^^^^^^^^^^
  File "/home/imran/Documents/Automation/Nornir/.MyNAPALMvenv/lib/python3.12/site-packages/nornir_napalm/plugins/tasks/napalm_get.py", line 32, in napalm_get
    device = task.host.get_connection(CONNECTION_NAME, task.nornir.config)
             ^^^^^^^^^^^^^^^^^^^^^^^^^^^^^^^^^^^^^^^^^^^^^^^^^^^^^^^^^^^^^
  File "/home/imran/Documents/Automation/Nornir/.MyNAPALMvenv/lib/python3.12/site-packages/nornir/core/inventory.py", line 494, in get_connection
    self.open_connection(
  File "/home/imran/Documents/Automation/Nornir/.MyNAPALMvenv/lib/python3.12/site-packages/nornir/core/inventory.py", line 546, in open_connection
    conn_obj.open(
  File "/home/imran/Documents/Automation/Nornir/.MyNAPALMvenv/lib/python3.12/site-packages/nornir_napalm/plugins/connections/__init__.py", line 57, in open
    connection.open()
  File "/home/imran/Documents/Automation/Nornir/.MyNAPALMvenv/lib/python3.12/site-packages/napalm/eos/eos.py", line 225, in open
    sh_ver = self._run_commands(["show version"])
             ^^^^^^^^^^^^^^^^^^^^^^^^^^^^^^^^^^^^
  File "/home/imran/Documents/Automation/Nornir/.MyNAPALMvenv/lib/python3.12/site-packages/napalm/eos/eos.py", line 279, in _run_commands
    return self.device.run_commands(commands, **kwargs)
           ^^^^^^^^^^^^^^^^^^^^^^^^^^^^^^^^^^^^^^^^^^^^
  File "/home/imran/Documents/Automation/Nornir/.MyNAPALMvenv/lib/python3.12/site-packages/pyeapi/client.py", line 899, in run_commands
    response = self._connection.execute(commands, encoding, **kwargs)
               ^^^^^^^^^^^^^^^^^^^^^^^^^^^^^^^^^^^^^^^^^^^^^^^^^^^^^^
  File "/home/imran/Documents/Automation/Nornir/.MyNAPALMvenv/lib/python3.12/site-packages/pyeapi/eapilib.py", line 629, in execute
    response = self.send(request)
               ^^^^^^^^^^^^^^^^^^
  File "/home/imran/Documents/Automation/Nornir/.MyNAPALMvenv/lib/python3.12/site-packages/pyeapi/eapilib.py", line 473, in send
    raise ConnectionError(str(self), error_msg)
pyeapi.eapilib.ConnectionError: Socket error during eAPI connection: [Errno 111] Connection refused

2024-08-27 23:27:33,946 - nornir.core.task -    ERROR -      start() - Host 'vEOS2': task 'get_device_info' failed with traceback:
Traceback (most recent call last):
  File "/home/imran/Documents/Automation/Nornir/.MyNAPALMvenv/lib/python3.12/site-packages/nornir/core/task.py", line 99, in start
    r = self.task(self, **self.params)
        ^^^^^^^^^^^^^^^^^^^^^^^^^^^^^^
  File "/home/imran/Documents/Automation/Nornir/Runbooks/Multi_Vendor_Lab4/NAPALM_Lab1.py", line 8, in get_device_info
    task.run (task=napalm_get, getters=['get_facts'])
  File "/home/imran/Documents/Automation/Nornir/.MyNAPALMvenv/lib/python3.12/site-packages/nornir/core/task.py", line 174, in run
    raise NornirSubTaskError(task=run_task, result=r)
nornir.core.exceptions.NornirSubTaskError: Subtask: napalm_get (failed)


2024-08-27 23:27:33,949 - nornir.core.task -    ERROR -      start() - Host 'vN9K-SW': task 'napalm_get' failed with traceback:
Traceback (most recent call last):
  File "/home/imran/Documents/Automation/Nornir/.MyNAPALMvenv/lib/python3.12/site-packages/urllib3/connection.py", line 196, in _new_conn
    sock = connection.create_connection(
           ^^^^^^^^^^^^^^^^^^^^^^^^^^^^^
  File "/home/imran/Documents/Automation/Nornir/.MyNAPALMvenv/lib/python3.12/site-packages/urllib3/util/connection.py", line 85, in create_connection
    raise err
  File "/home/imran/Documents/Automation/Nornir/.MyNAPALMvenv/lib/python3.12/site-packages/urllib3/util/connection.py", line 73, in create_connection
    sock.connect(sa)
ConnectionRefusedError: [Errno 111] Connection refused

The above exception was the direct cause of the following exception:

Traceback (most recent call last):
  File "/home/imran/Documents/Automation/Nornir/.MyNAPALMvenv/lib/python3.12/site-packages/urllib3/connectionpool.py", line 789, in urlopen
    response = self._make_request(
               ^^^^^^^^^^^^^^^^^^^
  File "/home/imran/Documents/Automation/Nornir/.MyNAPALMvenv/lib/python3.12/site-packages/urllib3/connectionpool.py", line 490, in _make_request
    raise new_e
  File "/home/imran/Documents/Automation/Nornir/.MyNAPALMvenv/lib/python3.12/site-packages/urllib3/connectionpool.py", line 466, in _make_request
    self._validate_conn(conn)
  File "/home/imran/Documents/Automation/Nornir/.MyNAPALMvenv/lib/python3.12/site-packages/urllib3/connectionpool.py", line 1095, in _validate_conn
    conn.connect()
  File "/home/imran/Documents/Automation/Nornir/.MyNAPALMvenv/lib/python3.12/site-packages/urllib3/connection.py", line 615, in connect
    self.sock = sock = self._new_conn()
                       ^^^^^^^^^^^^^^^^
  File "/home/imran/Documents/Automation/Nornir/.MyNAPALMvenv/lib/python3.12/site-packages/urllib3/connection.py", line 211, in _new_conn
    raise NewConnectionError(
urllib3.exceptions.NewConnectionError: <urllib3.connection.HTTPSConnection object at 0x7dc9e5944740>: Failed to establish a new connection: [Errno 111] Connection refused

The above exception was the direct cause of the following exception:

Traceback (most recent call last):
  File "/home/imran/Documents/Automation/Nornir/.MyNAPALMvenv/lib/python3.12/site-packages/requests/adapters.py", line 667, in send
    resp = conn.urlopen(
           ^^^^^^^^^^^^^
  File "/home/imran/Documents/Automation/Nornir/.MyNAPALMvenv/lib/python3.12/site-packages/urllib3/connectionpool.py", line 843, in urlopen
    retries = retries.increment(
              ^^^^^^^^^^^^^^^^^^
  File "/home/imran/Documents/Automation/Nornir/.MyNAPALMvenv/lib/python3.12/site-packages/urllib3/util/retry.py", line 519, in increment
    raise MaxRetryError(_pool, url, reason) from reason  # type: ignore[arg-type]
    ^^^^^^^^^^^^^^^^^^^^^^^^^^^^^^^^^^^^^^^^^^^^^^^^^^^
urllib3.exceptions.MaxRetryError: HTTPSConnectionPool(host='172.16.100.14', port=443): Max retries exceeded with url: /ins (Caused by NewConnectionError('<urllib3.connection.HTTPSConnection object at 0x7dc9e5944740>: Failed to establish a new connection: [Errno 111] Connection refused'))

During handling of the above exception, another exception occurred:

Traceback (most recent call last):
  File "/home/imran/Documents/Automation/Nornir/.MyNAPALMvenv/lib/python3.12/site-packages/napalm/nxapi_plumbing/api_client.py", line 96, in _send_request
    response = requests.post(
               ^^^^^^^^^^^^^^
  File "/home/imran/Documents/Automation/Nornir/.MyNAPALMvenv/lib/python3.12/site-packages/requests/api.py", line 115, in post
    return request("post", url, data=data, json=json, **kwargs)
           ^^^^^^^^^^^^^^^^^^^^^^^^^^^^^^^^^^^^^^^^^^^^^^^^^^^^
  File "/home/imran/Documents/Automation/Nornir/.MyNAPALMvenv/lib/python3.12/site-packages/requests/api.py", line 59, in request
    return session.request(method=method, url=url, **kwargs)
           ^^^^^^^^^^^^^^^^^^^^^^^^^^^^^^^^^^^^^^^^^^^^^^^^^
  File "/home/imran/Documents/Automation/Nornir/.MyNAPALMvenv/lib/python3.12/site-packages/requests/sessions.py", line 589, in request
    resp = self.send(prep, **send_kwargs)
           ^^^^^^^^^^^^^^^^^^^^^^^^^^^^^^
  File "/home/imran/Documents/Automation/Nornir/.MyNAPALMvenv/lib/python3.12/site-packages/requests/sessions.py", line 703, in send
    r = adapter.send(request, **kwargs)
        ^^^^^^^^^^^^^^^^^^^^^^^^^^^^^^^
  File "/home/imran/Documents/Automation/Nornir/.MyNAPALMvenv/lib/python3.12/site-packages/requests/adapters.py", line 700, in send
    raise ConnectionError(e, request=request)
requests.exceptions.ConnectionError: HTTPSConnectionPool(host='172.16.100.14', port=443): Max retries exceeded with url: /ins (Caused by NewConnectionError('<urllib3.connection.HTTPSConnection object at 0x7dc9e5944740>: Failed to establish a new connection: [Errno 111] Connection refused'))

During handling of the above exception, another exception occurred:

Traceback (most recent call last):
  File "/home/imran/Documents/Automation/Nornir/.MyNAPALMvenv/lib/python3.12/site-packages/napalm/nxos/nxos.py", line 824, in open
    self._send_command("show hostname")
  File "/home/imran/Documents/Automation/Nornir/.MyNAPALMvenv/lib/python3.12/site-packages/napalm/nxos/nxos.py", line 841, in _send_command
    return self.device.show(command, raw_text=raw_text)
           ^^^^^^^^^^^^^^^^^^^^^^^^^^^^^^^^^^^^^^^^^^^^
  File "/home/imran/Documents/Automation/Nornir/.MyNAPALMvenv/lib/python3.12/site-packages/napalm/nxapi_plumbing/device.py", line 70, in show
    result = self.show_list(commands, raw_text)
             ^^^^^^^^^^^^^^^^^^^^^^^^^^^^^^^^^^
  File "/home/imran/Documents/Automation/Nornir/.MyNAPALMvenv/lib/python3.12/site-packages/napalm/nxapi_plumbing/device.py", line 98, in show_list
    return self.api._nxapi_command(commands, method=cmd_method)
           ^^^^^^^^^^^^^^^^^^^^^^^^^^^^^^^^^^^^^^^^^^^^^^^^^^^^
  File "/home/imran/Documents/Automation/Nornir/.MyNAPALMvenv/lib/python3.12/site-packages/napalm/nxapi_plumbing/api_client.py", line 137, in _nxapi_command
    response = self._send_request(commands, method=method)
               ^^^^^^^^^^^^^^^^^^^^^^^^^^^^^^^^^^^^^^^^^^^
  File "/home/imran/Documents/Automation/Nornir/.MyNAPALMvenv/lib/python3.12/site-packages/napalm/nxapi_plumbing/api_client.py", line 105, in _send_request
    raise NXAPIConnectionError(str(e))
napalm.nxapi_plumbing.errors.NXAPIConnectionError: HTTPSConnectionPool(host='172.16.100.14', port=443): Max retries exceeded with url: /ins (Caused by NewConnectionError('<urllib3.connection.HTTPSConnection object at 0x7dc9e5944740>: Failed to establish a new connection: [Errno 111] Connection refused'))

During handling of the above exception, another exception occurred:

Traceback (most recent call last):
  File "/home/imran/Documents/Automation/Nornir/.MyNAPALMvenv/lib/python3.12/site-packages/nornir/core/task.py", line 99, in start
    r = self.task(self, **self.params)
        ^^^^^^^^^^^^^^^^^^^^^^^^^^^^^^
  File "/home/imran/Documents/Automation/Nornir/.MyNAPALMvenv/lib/python3.12/site-packages/nornir_napalm/plugins/tasks/napalm_get.py", line 32, in napalm_get
    device = task.host.get_connection(CONNECTION_NAME, task.nornir.config)
             ^^^^^^^^^^^^^^^^^^^^^^^^^^^^^^^^^^^^^^^^^^^^^^^^^^^^^^^^^^^^^
  File "/home/imran/Documents/Automation/Nornir/.MyNAPALMvenv/lib/python3.12/site-packages/nornir/core/inventory.py", line 494, in get_connection
    self.open_connection(
  File "/home/imran/Documents/Automation/Nornir/.MyNAPALMvenv/lib/python3.12/site-packages/nornir/core/inventory.py", line 546, in open_connection
    conn_obj.open(
  File "/home/imran/Documents/Automation/Nornir/.MyNAPALMvenv/lib/python3.12/site-packages/nornir_napalm/plugins/connections/__init__.py", line 57, in open
    connection.open()
  File "/home/imran/Documents/Automation/Nornir/.MyNAPALMvenv/lib/python3.12/site-packages/napalm/nxos/nxos.py", line 827, in open
    raise ConnectionException("Cannot connect to {}".format(self.hostname))
napalm.base.exceptions.ConnectionException: Cannot connect to 172.16.100.14

2024-08-27 23:27:33,949 - nornir.core.task -    ERROR -      start() - Host 'vN9K-SW': task 'get_device_info' failed with traceback:
Traceback (most recent call last):
  File "/home/imran/Documents/Automation/Nornir/.MyNAPALMvenv/lib/python3.12/site-packages/nornir/core/task.py", line 99, in start
    r = self.task(self, **self.params)
        ^^^^^^^^^^^^^^^^^^^^^^^^^^^^^^
  File "/home/imran/Documents/Automation/Nornir/Runbooks/Multi_Vendor_Lab4/NAPALM_Lab1.py", line 8, in get_device_info
    task.run (task=napalm_get, getters=['get_facts'])
  File "/home/imran/Documents/Automation/Nornir/.MyNAPALMvenv/lib/python3.12/site-packages/nornir/core/task.py", line 174, in run
    raise NornirSubTaskError(task=run_task, result=r)
nornir.core.exceptions.NornirSubTaskError: Subtask: napalm_get (failed)


2024-08-27 23:35:35,281 -  nornir.core -     INFO -        run() - Running task 'get_device_info' with args {} on 1 hosts
2024-08-27 23:37:39,213 -  nornir.core -     INFO -        run() - Running task 'get_device_info' with args {} on 1 hosts
2024-08-27 23:38:49,811 -  nornir.core -     INFO -        run() - Running task 'get_device_info' with args {} on 2 hosts
2024-08-27 23:38:49,829 - nornir.core.task -    ERROR -      start() - Host 'vEOS2': task 'napalm_get' failed with traceback:
Traceback (most recent call last):
  File "/home/imran/Documents/Automation/Nornir/.MyNAPALMvenv/lib/python3.12/site-packages/pyeapi/eapilib.py", line 435, in send
    self.transport.endheaders(message_body=data)
  File "/usr/lib/python3.12/http/client.py", line 1331, in endheaders
    self._send_output(message_body, encode_chunked=encode_chunked)
  File "/usr/lib/python3.12/http/client.py", line 1091, in _send_output
    self.send(msg)
  File "/usr/lib/python3.12/http/client.py", line 1035, in send
    self.connect()
  File "/usr/lib/python3.12/http/client.py", line 1470, in connect
    super().connect()
  File "/usr/lib/python3.12/http/client.py", line 1001, in connect
    self.sock = self._create_connection(
                ^^^^^^^^^^^^^^^^^^^^^^^^
  File "/usr/lib/python3.12/socket.py", line 852, in create_connection
    raise exceptions[0]
  File "/usr/lib/python3.12/socket.py", line 837, in create_connection
    sock.connect(sa)
ConnectionRefusedError: [Errno 111] Connection refused

During handling of the above exception, another exception occurred:

Traceback (most recent call last):
  File "/home/imran/Documents/Automation/Nornir/.MyNAPALMvenv/lib/python3.12/site-packages/nornir/core/task.py", line 99, in start
    r = self.task(self, **self.params)
        ^^^^^^^^^^^^^^^^^^^^^^^^^^^^^^
  File "/home/imran/Documents/Automation/Nornir/.MyNAPALMvenv/lib/python3.12/site-packages/nornir_napalm/plugins/tasks/napalm_get.py", line 32, in napalm_get
    device = task.host.get_connection(CONNECTION_NAME, task.nornir.config)
             ^^^^^^^^^^^^^^^^^^^^^^^^^^^^^^^^^^^^^^^^^^^^^^^^^^^^^^^^^^^^^
  File "/home/imran/Documents/Automation/Nornir/.MyNAPALMvenv/lib/python3.12/site-packages/nornir/core/inventory.py", line 494, in get_connection
    self.open_connection(
  File "/home/imran/Documents/Automation/Nornir/.MyNAPALMvenv/lib/python3.12/site-packages/nornir/core/inventory.py", line 546, in open_connection
    conn_obj.open(
  File "/home/imran/Documents/Automation/Nornir/.MyNAPALMvenv/lib/python3.12/site-packages/nornir_napalm/plugins/connections/__init__.py", line 57, in open
    connection.open()
  File "/home/imran/Documents/Automation/Nornir/.MyNAPALMvenv/lib/python3.12/site-packages/napalm/eos/eos.py", line 225, in open
    sh_ver = self._run_commands(["show version"])
             ^^^^^^^^^^^^^^^^^^^^^^^^^^^^^^^^^^^^
  File "/home/imran/Documents/Automation/Nornir/.MyNAPALMvenv/lib/python3.12/site-packages/napalm/eos/eos.py", line 279, in _run_commands
    return self.device.run_commands(commands, **kwargs)
           ^^^^^^^^^^^^^^^^^^^^^^^^^^^^^^^^^^^^^^^^^^^^
  File "/home/imran/Documents/Automation/Nornir/.MyNAPALMvenv/lib/python3.12/site-packages/pyeapi/client.py", line 899, in run_commands
    response = self._connection.execute(commands, encoding, **kwargs)
               ^^^^^^^^^^^^^^^^^^^^^^^^^^^^^^^^^^^^^^^^^^^^^^^^^^^^^^
  File "/home/imran/Documents/Automation/Nornir/.MyNAPALMvenv/lib/python3.12/site-packages/pyeapi/eapilib.py", line 629, in execute
    response = self.send(request)
               ^^^^^^^^^^^^^^^^^^
  File "/home/imran/Documents/Automation/Nornir/.MyNAPALMvenv/lib/python3.12/site-packages/pyeapi/eapilib.py", line 473, in send
    raise ConnectionError(str(self), error_msg)
pyeapi.eapilib.ConnectionError: Socket error during eAPI connection: [Errno 111] Connection refused

2024-08-27 23:38:49,831 - nornir.core.task -    ERROR -      start() - Host 'vEOS2': task 'get_device_info' failed with traceback:
Traceback (most recent call last):
  File "/home/imran/Documents/Automation/Nornir/.MyNAPALMvenv/lib/python3.12/site-packages/nornir/core/task.py", line 99, in start
    r = self.task(self, **self.params)
        ^^^^^^^^^^^^^^^^^^^^^^^^^^^^^^
  File "/home/imran/Documents/Automation/Nornir/Runbooks/Multi_Vendor_Lab4/NAPALM_Lab1.py", line 8, in get_device_info
    task.run (task=napalm_get, getters=["get_facts", "get_interfaces"])
  File "/home/imran/Documents/Automation/Nornir/.MyNAPALMvenv/lib/python3.12/site-packages/nornir/core/task.py", line 174, in run
    raise NornirSubTaskError(task=run_task, result=r)
nornir.core.exceptions.NornirSubTaskError: Subtask: napalm_get (failed)


2024-08-27 23:40:19,252 -  nornir.core -     INFO -        run() - Running task 'get_device_info' with args {} on 2 hosts
2024-08-27 23:41:40,682 -  nornir.core -     INFO -        run() - Running task 'get_device_info' with args {} on 3 hosts
2024-08-27 23:41:40,705 - nornir.core.task -    ERROR -      start() - Host 'vN9K-SW': task 'napalm_get' failed with traceback:
Traceback (most recent call last):
  File "/home/imran/Documents/Automation/Nornir/.MyNAPALMvenv/lib/python3.12/site-packages/urllib3/connection.py", line 196, in _new_conn
    sock = connection.create_connection(
           ^^^^^^^^^^^^^^^^^^^^^^^^^^^^^
  File "/home/imran/Documents/Automation/Nornir/.MyNAPALMvenv/lib/python3.12/site-packages/urllib3/util/connection.py", line 85, in create_connection
    raise err
  File "/home/imran/Documents/Automation/Nornir/.MyNAPALMvenv/lib/python3.12/site-packages/urllib3/util/connection.py", line 73, in create_connection
    sock.connect(sa)
ConnectionRefusedError: [Errno 111] Connection refused

The above exception was the direct cause of the following exception:

Traceback (most recent call last):
  File "/home/imran/Documents/Automation/Nornir/.MyNAPALMvenv/lib/python3.12/site-packages/urllib3/connectionpool.py", line 789, in urlopen
    response = self._make_request(
               ^^^^^^^^^^^^^^^^^^^
  File "/home/imran/Documents/Automation/Nornir/.MyNAPALMvenv/lib/python3.12/site-packages/urllib3/connectionpool.py", line 490, in _make_request
    raise new_e
  File "/home/imran/Documents/Automation/Nornir/.MyNAPALMvenv/lib/python3.12/site-packages/urllib3/connectionpool.py", line 466, in _make_request
    self._validate_conn(conn)
  File "/home/imran/Documents/Automation/Nornir/.MyNAPALMvenv/lib/python3.12/site-packages/urllib3/connectionpool.py", line 1095, in _validate_conn
    conn.connect()
  File "/home/imran/Documents/Automation/Nornir/.MyNAPALMvenv/lib/python3.12/site-packages/urllib3/connection.py", line 615, in connect
    self.sock = sock = self._new_conn()
                       ^^^^^^^^^^^^^^^^
  File "/home/imran/Documents/Automation/Nornir/.MyNAPALMvenv/lib/python3.12/site-packages/urllib3/connection.py", line 211, in _new_conn
    raise NewConnectionError(
urllib3.exceptions.NewConnectionError: <urllib3.connection.HTTPSConnection object at 0x7491b4220920>: Failed to establish a new connection: [Errno 111] Connection refused

The above exception was the direct cause of the following exception:

Traceback (most recent call last):
  File "/home/imran/Documents/Automation/Nornir/.MyNAPALMvenv/lib/python3.12/site-packages/requests/adapters.py", line 667, in send
    resp = conn.urlopen(
           ^^^^^^^^^^^^^
  File "/home/imran/Documents/Automation/Nornir/.MyNAPALMvenv/lib/python3.12/site-packages/urllib3/connectionpool.py", line 843, in urlopen
    retries = retries.increment(
              ^^^^^^^^^^^^^^^^^^
  File "/home/imran/Documents/Automation/Nornir/.MyNAPALMvenv/lib/python3.12/site-packages/urllib3/util/retry.py", line 519, in increment
    raise MaxRetryError(_pool, url, reason) from reason  # type: ignore[arg-type]
    ^^^^^^^^^^^^^^^^^^^^^^^^^^^^^^^^^^^^^^^^^^^^^^^^^^^
urllib3.exceptions.MaxRetryError: HTTPSConnectionPool(host='172.16.100.14', port=443): Max retries exceeded with url: /ins (Caused by NewConnectionError('<urllib3.connection.HTTPSConnection object at 0x7491b4220920>: Failed to establish a new connection: [Errno 111] Connection refused'))

During handling of the above exception, another exception occurred:

Traceback (most recent call last):
  File "/home/imran/Documents/Automation/Nornir/.MyNAPALMvenv/lib/python3.12/site-packages/napalm/nxapi_plumbing/api_client.py", line 96, in _send_request
    response = requests.post(
               ^^^^^^^^^^^^^^
  File "/home/imran/Documents/Automation/Nornir/.MyNAPALMvenv/lib/python3.12/site-packages/requests/api.py", line 115, in post
    return request("post", url, data=data, json=json, **kwargs)
           ^^^^^^^^^^^^^^^^^^^^^^^^^^^^^^^^^^^^^^^^^^^^^^^^^^^^
  File "/home/imran/Documents/Automation/Nornir/.MyNAPALMvenv/lib/python3.12/site-packages/requests/api.py", line 59, in request
    return session.request(method=method, url=url, **kwargs)
           ^^^^^^^^^^^^^^^^^^^^^^^^^^^^^^^^^^^^^^^^^^^^^^^^^
  File "/home/imran/Documents/Automation/Nornir/.MyNAPALMvenv/lib/python3.12/site-packages/requests/sessions.py", line 589, in request
    resp = self.send(prep, **send_kwargs)
           ^^^^^^^^^^^^^^^^^^^^^^^^^^^^^^
  File "/home/imran/Documents/Automation/Nornir/.MyNAPALMvenv/lib/python3.12/site-packages/requests/sessions.py", line 703, in send
    r = adapter.send(request, **kwargs)
        ^^^^^^^^^^^^^^^^^^^^^^^^^^^^^^^
  File "/home/imran/Documents/Automation/Nornir/.MyNAPALMvenv/lib/python3.12/site-packages/requests/adapters.py", line 700, in send
    raise ConnectionError(e, request=request)
requests.exceptions.ConnectionError: HTTPSConnectionPool(host='172.16.100.14', port=443): Max retries exceeded with url: /ins (Caused by NewConnectionError('<urllib3.connection.HTTPSConnection object at 0x7491b4220920>: Failed to establish a new connection: [Errno 111] Connection refused'))

During handling of the above exception, another exception occurred:

Traceback (most recent call last):
  File "/home/imran/Documents/Automation/Nornir/.MyNAPALMvenv/lib/python3.12/site-packages/napalm/nxos/nxos.py", line 824, in open
    self._send_command("show hostname")
  File "/home/imran/Documents/Automation/Nornir/.MyNAPALMvenv/lib/python3.12/site-packages/napalm/nxos/nxos.py", line 841, in _send_command
    return self.device.show(command, raw_text=raw_text)
           ^^^^^^^^^^^^^^^^^^^^^^^^^^^^^^^^^^^^^^^^^^^^
  File "/home/imran/Documents/Automation/Nornir/.MyNAPALMvenv/lib/python3.12/site-packages/napalm/nxapi_plumbing/device.py", line 70, in show
    result = self.show_list(commands, raw_text)
             ^^^^^^^^^^^^^^^^^^^^^^^^^^^^^^^^^^
  File "/home/imran/Documents/Automation/Nornir/.MyNAPALMvenv/lib/python3.12/site-packages/napalm/nxapi_plumbing/device.py", line 98, in show_list
    return self.api._nxapi_command(commands, method=cmd_method)
           ^^^^^^^^^^^^^^^^^^^^^^^^^^^^^^^^^^^^^^^^^^^^^^^^^^^^
  File "/home/imran/Documents/Automation/Nornir/.MyNAPALMvenv/lib/python3.12/site-packages/napalm/nxapi_plumbing/api_client.py", line 137, in _nxapi_command
    response = self._send_request(commands, method=method)
               ^^^^^^^^^^^^^^^^^^^^^^^^^^^^^^^^^^^^^^^^^^^
  File "/home/imran/Documents/Automation/Nornir/.MyNAPALMvenv/lib/python3.12/site-packages/napalm/nxapi_plumbing/api_client.py", line 105, in _send_request
    raise NXAPIConnectionError(str(e))
napalm.nxapi_plumbing.errors.NXAPIConnectionError: HTTPSConnectionPool(host='172.16.100.14', port=443): Max retries exceeded with url: /ins (Caused by NewConnectionError('<urllib3.connection.HTTPSConnection object at 0x7491b4220920>: Failed to establish a new connection: [Errno 111] Connection refused'))

During handling of the above exception, another exception occurred:

Traceback (most recent call last):
  File "/home/imran/Documents/Automation/Nornir/.MyNAPALMvenv/lib/python3.12/site-packages/nornir/core/task.py", line 99, in start
    r = self.task(self, **self.params)
        ^^^^^^^^^^^^^^^^^^^^^^^^^^^^^^
  File "/home/imran/Documents/Automation/Nornir/.MyNAPALMvenv/lib/python3.12/site-packages/nornir_napalm/plugins/tasks/napalm_get.py", line 32, in napalm_get
    device = task.host.get_connection(CONNECTION_NAME, task.nornir.config)
             ^^^^^^^^^^^^^^^^^^^^^^^^^^^^^^^^^^^^^^^^^^^^^^^^^^^^^^^^^^^^^
  File "/home/imran/Documents/Automation/Nornir/.MyNAPALMvenv/lib/python3.12/site-packages/nornir/core/inventory.py", line 494, in get_connection
    self.open_connection(
  File "/home/imran/Documents/Automation/Nornir/.MyNAPALMvenv/lib/python3.12/site-packages/nornir/core/inventory.py", line 546, in open_connection
    conn_obj.open(
  File "/home/imran/Documents/Automation/Nornir/.MyNAPALMvenv/lib/python3.12/site-packages/nornir_napalm/plugins/connections/__init__.py", line 57, in open
    connection.open()
  File "/home/imran/Documents/Automation/Nornir/.MyNAPALMvenv/lib/python3.12/site-packages/napalm/nxos/nxos.py", line 827, in open
    raise ConnectionException("Cannot connect to {}".format(self.hostname))
napalm.base.exceptions.ConnectionException: Cannot connect to 172.16.100.14

2024-08-27 23:41:40,707 - nornir.core.task -    ERROR -      start() - Host 'vN9K-SW': task 'get_device_info' failed with traceback:
Traceback (most recent call last):
  File "/home/imran/Documents/Automation/Nornir/.MyNAPALMvenv/lib/python3.12/site-packages/nornir/core/task.py", line 99, in start
    r = self.task(self, **self.params)
        ^^^^^^^^^^^^^^^^^^^^^^^^^^^^^^
  File "/home/imran/Documents/Automation/Nornir/Runbooks/Multi_Vendor_Lab4/NAPALM_Lab1.py", line 8, in get_device_info
    task.run (task=napalm_get, getters=["get_facts"])
  File "/home/imran/Documents/Automation/Nornir/.MyNAPALMvenv/lib/python3.12/site-packages/nornir/core/task.py", line 174, in run
    raise NornirSubTaskError(task=run_task, result=r)
nornir.core.exceptions.NornirSubTaskError: Subtask: napalm_get (failed)


2024-08-27 23:44:16,596 -  nornir.core -     INFO -        run() - Running task 'get_device_info' with args {} on 3 hosts
2024-08-27 23:46:34,920 -  nornir.core -     INFO -        run() - Running task 'get_device_info' with args {} on 4 hosts
2024-08-27 23:46:34,937 - nornir.core.task -    ERROR -      start() - Host 'EOS2': task 'napalm_get' failed with traceback:
Traceback (most recent call last):
  File "/home/imran/Documents/Automation/Nornir/.MyNAPALMvenv/lib/python3.12/site-packages/pyeapi/eapilib.py", line 435, in send
    self.transport.endheaders(message_body=data)
  File "/usr/lib/python3.12/http/client.py", line 1331, in endheaders
    self._send_output(message_body, encode_chunked=encode_chunked)
  File "/usr/lib/python3.12/http/client.py", line 1091, in _send_output
    self.send(msg)
  File "/usr/lib/python3.12/http/client.py", line 1035, in send
    self.connect()
  File "/usr/lib/python3.12/http/client.py", line 1470, in connect
    super().connect()
  File "/usr/lib/python3.12/http/client.py", line 1001, in connect
    self.sock = self._create_connection(
                ^^^^^^^^^^^^^^^^^^^^^^^^
  File "/usr/lib/python3.12/socket.py", line 852, in create_connection
    raise exceptions[0]
  File "/usr/lib/python3.12/socket.py", line 837, in create_connection
    sock.connect(sa)
ConnectionRefusedError: [Errno 111] Connection refused

During handling of the above exception, another exception occurred:

Traceback (most recent call last):
  File "/home/imran/Documents/Automation/Nornir/.MyNAPALMvenv/lib/python3.12/site-packages/nornir/core/task.py", line 99, in start
    r = self.task(self, **self.params)
        ^^^^^^^^^^^^^^^^^^^^^^^^^^^^^^
  File "/home/imran/Documents/Automation/Nornir/.MyNAPALMvenv/lib/python3.12/site-packages/nornir_napalm/plugins/tasks/napalm_get.py", line 32, in napalm_get
    device = task.host.get_connection(CONNECTION_NAME, task.nornir.config)
             ^^^^^^^^^^^^^^^^^^^^^^^^^^^^^^^^^^^^^^^^^^^^^^^^^^^^^^^^^^^^^
  File "/home/imran/Documents/Automation/Nornir/.MyNAPALMvenv/lib/python3.12/site-packages/nornir/core/inventory.py", line 494, in get_connection
    self.open_connection(
  File "/home/imran/Documents/Automation/Nornir/.MyNAPALMvenv/lib/python3.12/site-packages/nornir/core/inventory.py", line 546, in open_connection
    conn_obj.open(
  File "/home/imran/Documents/Automation/Nornir/.MyNAPALMvenv/lib/python3.12/site-packages/nornir_napalm/plugins/connections/__init__.py", line 57, in open
    connection.open()
  File "/home/imran/Documents/Automation/Nornir/.MyNAPALMvenv/lib/python3.12/site-packages/napalm/eos/eos.py", line 225, in open
    sh_ver = self._run_commands(["show version"])
             ^^^^^^^^^^^^^^^^^^^^^^^^^^^^^^^^^^^^
  File "/home/imran/Documents/Automation/Nornir/.MyNAPALMvenv/lib/python3.12/site-packages/napalm/eos/eos.py", line 279, in _run_commands
    return self.device.run_commands(commands, **kwargs)
           ^^^^^^^^^^^^^^^^^^^^^^^^^^^^^^^^^^^^^^^^^^^^
  File "/home/imran/Documents/Automation/Nornir/.MyNAPALMvenv/lib/python3.12/site-packages/pyeapi/client.py", line 899, in run_commands
    response = self._connection.execute(commands, encoding, **kwargs)
               ^^^^^^^^^^^^^^^^^^^^^^^^^^^^^^^^^^^^^^^^^^^^^^^^^^^^^^
  File "/home/imran/Documents/Automation/Nornir/.MyNAPALMvenv/lib/python3.12/site-packages/pyeapi/eapilib.py", line 629, in execute
    response = self.send(request)
               ^^^^^^^^^^^^^^^^^^
  File "/home/imran/Documents/Automation/Nornir/.MyNAPALMvenv/lib/python3.12/site-packages/pyeapi/eapilib.py", line 473, in send
    raise ConnectionError(str(self), error_msg)
pyeapi.eapilib.ConnectionError: Socket error during eAPI connection: [Errno 111] Connection refused

2024-08-27 23:46:34,940 - nornir.core.task -    ERROR -      start() - Host 'EOS2': task 'get_device_info' failed with traceback:
Traceback (most recent call last):
  File "/home/imran/Documents/Automation/Nornir/.MyNAPALMvenv/lib/python3.12/site-packages/nornir/core/task.py", line 99, in start
    r = self.task(self, **self.params)
        ^^^^^^^^^^^^^^^^^^^^^^^^^^^^^^
  File "/home/imran/Documents/Automation/Nornir/Runbooks/Multi_Vendor_Lab4/NAPALM_Lab1.py", line 8, in get_device_info
    task.run (task=napalm_get, getters=["get_facts"])
  File "/home/imran/Documents/Automation/Nornir/.MyNAPALMvenv/lib/python3.12/site-packages/nornir/core/task.py", line 174, in run
    raise NornirSubTaskError(task=run_task, result=r)
nornir.core.exceptions.NornirSubTaskError: Subtask: napalm_get (failed)


2024-08-28 00:06:29,505 -  nornir.core -     INFO -        run() - Running task 'get_device_info' with args {} on 4 hosts
2024-08-28 00:12:53,047 -  nornir.core -     INFO -        run() - Running task 'get_device_info' with args {} on 4 hosts
2024-08-28 00:13:58,428 -  nornir.core -     INFO -        run() - Running task 'get_device_info' with args {} on 4 hosts
